ERROR:ml_pipeline.predictor:Failed to load model: RESOURCE_DOES_NOT_EXIST: Registered Model with name=demand_forecasting_xgb not found
INFO:ml_pipeline.orchestrator:Starting training pipeline
INFO:ml_pipeline.extractor:Loading Orders and OrderDetails as DataFrames...
INFO:ml_pipeline.extractor:Extracted data successfully
INFO:ml_pipeline.extractor:                                     Id  ...  order_date
0  0086f603-c118-4ff4-bcca-6e1480413363  ...  2025-07-01
1  1517200a-e53b-470d-a7c4-a34830ccc9e0  ...  2025-07-15
2  17c56774-0086-466f-ab9f-e0a07afc3960  ...  2025-06-29
3  25b2effb-b716-4e9c-b60a-b85c480bb1f3  ...  2025-07-12
4  25dceac3-7639-49c5-b65f-7b25d7469d5e  ...  2025-06-29

[5 rows x 22 columns]
INFO:ml_pipeline.preprocessor:Starting feature engineering
ERROR:ml_pipeline.orchestrator:Training pipeline failed: Can only use .dt accessor with datetimelike values
[31mERROR[0m:    Traceback (most recent call last):
  File "/Users/onyekachiobute/Documents/RestaurantAIServices/DemandForecastService/.venv/lib/python3.13/site-packages/starlette/routing.py", line 694, in lifespan
    async with self.lifespan_context(app) as maybe_state:
               ~~~~~~~~~~~~~~~~~~~~~^^^^^
  File "/Library/Frameworks/Python.framework/Versions/3.13/lib/python3.13/contextlib.py", line 214, in __aenter__
    return await anext(self.gen)
           ^^^^^^^^^^^^^^^^^^^^^
  File "/Users/onyekachiobute/Documents/RestaurantAIServices/DemandForecastService/.venv/lib/python3.13/site-packages/fastapi/routing.py", line 134, in merged_lifespan
    async with original_context(app) as maybe_original_state:
               ~~~~~~~~~~~~~~~~^^^^^
  File "/Library/Frameworks/Python.framework/Versions/3.13/lib/python3.13/contextlib.py", line 214, in __aenter__
    return await anext(self.gen)
           ^^^^^^^^^^^^^^^^^^^^^
  File "/Users/onyekachiobute/Documents/RestaurantAIServices/DemandForecastService/main.py", line 29, in lifespan
    orchestrator.run_training_pipeline()
    ~~~~~~~~~~~~~~~~~~~~~~~~~~~~~~~~~~^^
  File "/Users/onyekachiobute/Documents/RestaurantAIServices/DemandForecastService/ml_pipeline/orchestrator.py", line 41, in run_training_pipeline
    features = self.feature_engineer.create_features(df)
  File "/Users/onyekachiobute/Documents/RestaurantAIServices/DemandForecastService/ml_pipeline/preprocessor.py", line 23, in create_features
    df['hour'] = df['order_date'].dt.hour
                 ^^^^^^^^^^^^^^^^^^^
  File "/Users/onyekachiobute/Documents/RestaurantAIServices/DemandForecastService/.venv/lib/python3.13/site-packages/pandas/core/generic.py", line 6318, in __getattr__
    return object.__getattribute__(self, name)
           ~~~~~~~~~~~~~~~~~~~~~~~^^^^^^^^^^^^
  File "/Users/onyekachiobute/Documents/RestaurantAIServices/DemandForecastService/.venv/lib/python3.13/site-packages/pandas/core/accessor.py", line 224, in __get__
    accessor_obj = self._accessor(obj)
  File "/Users/onyekachiobute/Documents/RestaurantAIServices/DemandForecastService/.venv/lib/python3.13/site-packages/pandas/core/indexes/accessors.py", line 643, in __new__
    raise AttributeError("Can only use .dt accessor with datetimelike values")
AttributeError: Can only use .dt accessor with datetimelike values. Did you mean: 'at'?

[31mERROR[0m:    Application startup failed. Exiting.
