[31mERROR[0m:    Traceback (most recent call last):
  File "/Users/onyekachiobute/Documents/RestaurantAIServices/DemandForecastService/.venv/lib/python3.13/site-packages/starlette/routing.py", line 694, in lifespan
    async with self.lifespan_context(app) as maybe_state:
               ~~~~~~~~~~~~~~~~~~~~~^^^^^
  File "/Library/Frameworks/Python.framework/Versions/3.13/lib/python3.13/contextlib.py", line 214, in __aenter__
    return await anext(self.gen)
           ^^^^^^^^^^^^^^^^^^^^^
  File "/Users/onyekachiobute/Documents/RestaurantAIServices/DemandForecastService/.venv/lib/python3.13/site-packages/fastapi/routing.py", line 134, in merged_lifespan
    async with original_context(app) as maybe_original_state:
               ~~~~~~~~~~~~~~~~^^^^^
  File "/Library/Frameworks/Python.framework/Versions/3.13/lib/python3.13/contextlib.py", line 214, in __aenter__
    return await anext(self.gen)
           ^^^^^^^^^^^^^^^^^^^^^
  File "/Users/onyekachiobute/Documents/RestaurantAIServices/DemandForecastService/main.py", line 24, in lifespan
    orchestrator = MLPipelineOrchestrator()
  File "/Users/onyekachiobute/Documents/RestaurantAIServices/DemandForecastService/ml_pipeline/orchestrator.py", line 23, in __init__
    self.predictor = DemandPredictor(
                     ~~~~~~~~~~~~~~~^
        Config.MLFLOW_TRACKING_URI,
        ^^^^^^^^^^^^^^^^^^^^^^^^^^^
        Config.MODEL_NAME,
        ^^^^^^^^^^^^^^^^^^
        Config.PREDICTIONS_DB_URL
        ^^^^^^^^^^^^^^^^^^^^^^^^^
    )
    ^
  File "/Users/onyekachiobute/Documents/RestaurantAIServices/DemandForecastService/ml_pipeline/predictor.py", line 17, in __init__
    self.engine = create_engine(db_url)
                  ~~~~~~~~~~~~~^^^^^^^^
  File "<string>", line 2, in create_engine
  File "/Users/onyekachiobute/Documents/RestaurantAIServices/DemandForecastService/.venv/lib/python3.13/site-packages/sqlalchemy/util/deprecations.py", line 281, in warned
    return fn(*args, **kwargs)  # type: ignore[no-any-return]
  File "/Users/onyekachiobute/Documents/RestaurantAIServices/DemandForecastService/.venv/lib/python3.13/site-packages/sqlalchemy/engine/create.py", line 602, in create_engine
    dbapi = dbapi_meth(**dbapi_args)
  File "/Users/onyekachiobute/Documents/RestaurantAIServices/DemandForecastService/.venv/lib/python3.13/site-packages/sqlalchemy/dialects/postgresql/psycopg2.py", line 696, in import_dbapi
    import psycopg2
ModuleNotFoundError: No module named 'psycopg2'

[31mERROR[0m:    Application startup failed. Exiting.
